telegram.ext.updater - WARNING - Exiting immediately!
telegram.ext.updater - WARNING - Exiting immediately!
telegram.ext.updater - WARNING - Exiting immediately!
telegram.ext.dispatcher - ERROR - An uncaught error was raised while processing the update
Traceback (most recent call last):
  File "C:\Python34\lib\site-packages\telegram\ext\dispatcher.py", line 270, in process_update
    handler.handle_update(update, self)
  File "C:\Python34\lib\site-packages\telegram\ext\commandhandler.py", line 171, in handle_update
    return self.callback(dispatcher.bot, update, **optional_args)
  File "bot.py", line 32, in greet_user
    print(1/0)
ZeroDivisionError: division by zero
telegram.ext.dispatcher - ERROR - An uncaught error was raised while processing the update
Traceback (most recent call last):
  File "C:\Python34\lib\site-packages\telegram\ext\dispatcher.py", line 270, in process_update
    handler.handle_update(update, self)
  File "C:\Python34\lib\site-packages\telegram\ext\commandhandler.py", line 171, in handle_update
    return self.callback(dispatcher.bot, update, **optional_args)
  File "bot.py", line 33, in greet_user
    print(1/0)
ZeroDivisionError: division by zero
telegram.ext.dispatcher - ERROR - An uncaught error was raised while processing the update
Traceback (most recent call last):
  File "C:\Python34\lib\site-packages\telegram\ext\dispatcher.py", line 270, in process_update
    handler.handle_update(update, self)
  File "C:\Python34\lib\site-packages\telegram\ext\messagehandler.py", line 169, in handle_update
    return self.callback(dispatcher.bot, update, **optional_args)
  File "bot.py", line 39, in talk_to_me
    logging_info(user_text)
NameError: name 'logging_info' is not defined
telegram.ext.dispatcher - ERROR - An uncaught error was raised while processing the update
Traceback (most recent call last):
  File "C:\Python34\lib\site-packages\telegram\ext\dispatcher.py", line 270, in process_update
    handler.handle_update(update, self)
  File "C:\Python34\lib\site-packages\telegram\ext\messagehandler.py", line 169, in handle_update
    return self.callback(dispatcher.bot, update, **optional_args)
  File "bot.py", line 39, in talk_to_me
    logging_info(user_text)
NameError: name 'logging_info' is not defined
telegram.ext.updater - WARNING - Exiting immediately!
telegram.ext.dispatcher - ERROR - An uncaught error was raised while processing the update
Traceback (most recent call last):
  File "C:\Python34\lib\site-packages\telegram\ext\dispatcher.py", line 270, in process_update
    handler.handle_update(update, self)
  File "C:\Python34\lib\site-packages\telegram\ext\messagehandler.py", line 169, in handle_update
    return self.callback(dispatcher.bot, update, **optional_args)
  File "bot.py", line 38, in talk_to_me
    logging_info(user_text)
NameError: name 'logging_info' is not defined
telegram.ext.dispatcher - ERROR - An uncaught error was raised while processing the update
Traceback (most recent call last):
  File "C:\Python34\lib\site-packages\telegram\ext\dispatcher.py", line 270, in process_update
    handler.handle_update(update, self)
  File "C:\Python34\lib\site-packages\telegram\ext\commandhandler.py", line 171, in handle_update
    return self.callback(dispatcher.bot, update, **optional_args)
  File "bot.py", line 32, in greet_user
    print(1/0)
ZeroDivisionError: division by zero
telegram.ext.updater - WARNING - Exiting immediately!
root - INFO - dsa
telegram.ext.updater - WARNING - Exiting immediately!
root - INFO - dsfds
root - INFO - dsadsa
telegram.ext.updater - ERROR - Error while getting Updates: Timed out
telegram.ext.updater - WARNING - Exiting immediately!
